File: data/raw/0395_Mn5_220709.dc.dat
[Header]
TITLE,MPMS DC Measurement
BYAPP,MPMS Measurement,2.1,Summary
FILEOPENTIME, 1657387168.784000 7/9/2022, 1:19:28 PM

INFO, APPNAME, MPMS MultiVu Application, Revision 1.53,  Build 056

INFO, NAME, 0395_Mn
INFO, WEIGHT, 21.480
INFO, AREA, 0.000
INFO, LENGTH, 0.000
INFO, SHAPE,
INFO, COMMENT,
INFO, SEQUENCE FILE: 0395_Mn5_220709.seq


INFO, BACKGROUND DATA FILE:, None


STARTUPAXIS,X,4,LINEAR,AUTO,0.000000,0.000000
STARTUPAXIS,Y1,5,LINEAR,AUTO,0.000000,0.000000


STARTUPGROUP,Longitudinal
FIELDGROUP,Longitudinal,1,2,3,4,5,6,7,8,9,15,16,17,18,27,28
FIELDGROUP,Transverse,1,2,3,4,10,11,12,13,14,19,20,21,22,27,28

PLOT_APPEARANCE,ALL,HORZ_GRID_ON,VERT_GRID_ON,MARKERS_AND_LINES

[Data]
Time,Comment,Field (Oe),Temperature (K),Long Moment (emu),Long Scan Std Dev,Long Algorithm,Long Reg Fit,Long Percent Error (%),Trans Moment (emu),Trans Scan Std Dev,Trans Algorithm,Trans Reg Fit,Trans Percent Error (%),Long Moment [w/o ABS] (emu),Long Scan Std Dev [w/o ABS],Long Reg Fit [w/o ABS],Long Percent Error [w/o ABS] (%),Trans Moment [w/o ABS] (emu),Trans Scan Std Dev [w/o ABS],Trans Reg Fit [w/o ABS],Trans Percent Error [w/o ABS] (%),Points per Scan,Scans per Measurement,Scan Length (cm),Delta Temp (K),Rot Position (deg),Error,EC Comp. Running,Using ABS,
1657387168.782,,1.000000e+002,5.002314e+000,3.230414e-002,1.319381e-004,3,9.675889e-001,4.084247e-001,,,,,,,,,,,,,,48,2,4.000000e+000,1.357794e-002,0.000000e+000,0,,0,
1657387426.963,,1.000000e+002,1.000019e+001,5.598803e-002,3.201843e-005,3,9.652750e-001,5.718800e-002,,,,,,,,,,,,,,48,2,4.000000e+000,3.884315e-003,0.000000e+000,0,,0,
1657387669.056,,1.000000e+002,1.499860e+001,6.201324e-002,1.206454e-006,3,9.647113e-001,1.945477e-003,,,,,,,,,,,,,,48,2,4.000000e+000,2.300262e-003,0.000000e+000,0,,0,
1657387894.801,,1.000000e+002,1.999851e+001,6.477239e-002,5.616067e-006,3,9.644932e-001,8.670465e-003,,,,,,,,,,,,,,48,2,4.000000e+000,4.650116e-003,0.000000e+000,0,,0,
1657388109.572,,1.000000e+002,2.500041e+001,6.239429e-002,3.105697e-006,3,9.647191e-001,4.977534e-003,,,,,,,,,,,,,,48,2,4.000000e+000,7.989883e-003,0.000000e+000,0,,0,
1657388308.105,,1.000000e+002,3.000093e+001,5.478266e-002,3.967072e-006,3,9.654092e-001,7.241474e-003,,,,,,,,,,,,,,48,2,4.000000e+000,4.171371e-003,0.000000e+000,0,,0,
1657388526.441,,1.000000e+002,3.500195e+001,4.185838e-002,5.268356e-006,3,9.667523e-001,1.258614e-002,,,,,,,,,,,,,,48,2,4.000000e+000,3.681183e-003,0.000000e+000,0,,0,
1657388763.076,,1.000000e+002,4.000209e+001,2.823581e-002,2.805430e-007,3,9.681352e-001,9.935717e-004,,,,,,,,,,,,,,48,2,4.000000e+000,4.699707e-003,0.000000e+000,0,,0,
1657389133.493,,1.000000e+002,4.500052e+001,1.853838e-002,3.940730e-006,3,9.687204e-001,2.125715e-002,,,,,,,,,,,,,,48,2,4.000000e+000,5.809784e-003,0.000000e+000,0,,0,
1657389488.249,,1.000000e+002,5.000034e+001,1.264542e-002,2.497201e-006,3,9.685725e-001,1.974788e-002,,,,,,,,,,,,,,48,2,4.000000e+000,7.030487e-003,0.000000e+000,0,,0,
1657389812.187,,1.000000e+002,5.499933e+001,9.022549e-003,2.549226e-006,3,9.685279e-001,2.825394e-002,,,,,,,,,,,,,,48,2,4.000000e+000,1.509094e-002,0.000000e+000,0,,0,
1657390173.689,,1.000000e+002,5.999244e+001,6.663322e-003,1.488640e-006,3,9.683268e-001,2.234081e-002,,,,,,,,,,,,,,48,2,4.000000e+000,3.952026e-003,0.000000e+000,0,,0,
1657390535.989,,1.000000e+002,6.499855e+001,5.054642e-003,3.053012e-006,3,9.684447e-001,6.040017e-002,,,,,,,,,,,,,,48,2,4.000000e+000,1.369476e-002,0.000000e+000,0,,0,
1657390915.437,,1.000000e+002,6.999126e+001,3.914508e-003,2.395456e-006,3,9.687060e-001,6.119429e-002,,,,,,,,,,,,,,48,2,4.000000e+000,1.305389e-002,0.000000e+000,0,,0,
1657391306.636,,1.000000e+002,7.499309e+001,3.089430e-003,2.128745e-006,3,9.690528e-001,6.890414e-002,,,,,,,,,,,,,,48,2,4.000000e+000,1.185608e-002,0.000000e+000,0,,0,
1657391739.857,,1.000000e+002,7.999815e+001,2.480563e-003,3.493579e-007,3,9.694784e-001,1.408381e-002,,,,,,,,,,,,,,48,2,4.000000e+000,1.669312e-002,0.000000e+000,0,,0,
1657392157.921,,1.000000e+002,8.499226e+001,2.023191e-003,1.232795e-006,3,9.700780e-001,6.093322e-002,,,,,,,,,,,,,,48,2,4.000000e+000,2.238464e-002,0.000000e+000,0,,0,
1657392583.315,,1.000000e+002,8.998834e+001,1.673538e-003,1.681264e-006,3,9.705514e-001,1.004617e-001,,,,,,,,,,,,,,48,2,4.000000e+000,2.899170e-002,0.000000e+000,0,,0,
1657393030.046,,1.000000e+002,9.498969e+001,1.404579e-003,1.172621e-006,3,9.711440e-001,8.348557e-002,,,,,,,,,,,,,,48,2,4.000000e+000,2.740479e-002,0.000000e+000,0,,0,
1657393478.711,,1.000000e+002,9.998535e+001,1.196164e-003,9.452583e-007,3,9.715089e-001,7.902413e-002,,,,,,,,,,,,,,48,2,4.000000e+000,2.507019e-002,0.000000e+000,0,,0,
1657393991.221,,1.000000e+002,1.099928e+002,9.002993e-004,5.956123e-007,3,9.720021e-001,6.615715e-002,,,,,,,,,,,,,,48,2,4.000000e+000,9.002686e-003,0.000000e+000,0,,0,
1657394539.005,,1.000000e+002,1.199944e+002,7.109938e-004,5.968059e-008,3,9.721776e-001,8.393968e-003,,,,,,,,,,,,,,48,2,4.000000e+000,7.003784e-003,0.000000e+000,0,,0,
1657395062.001,,1.000000e+002,1.299936e+002,5.818529e-004,5.577872e-007,3,9.723217e-001,9.586396e-002,,,,,,,,,,,,,,48,2,4.000000e+000,1.219177e-002,0.000000e+000,0,,0,
1657395582.187,,1.000000e+002,1.399908e+002,4.882180e-004,3.670974e-007,3,9.723027e-001,7.519129e-002,,,,,,,,,,,,,,48,2,4.000000e+000,1.390076e-002,0.000000e+000,0,,0,
1657396103.860,,1.000000e+002,1.499920e+002,4.177639e-004,2.867961e-007,3,9.723531e-001,6.865028e-002,,,,,,,,,,,,,,48,2,4.000000e+000,5.294800e-003,0.000000e+000,0,,0,
1657396623.424,,1.000000e+002,1.599890e+002,3.633331e-004,3.613557e-007,3,9.723809e-001,9.945577e-002,,,,,,,,,,,,,,48,2,4.000000e+000,1.179504e-002,0.000000e+000,0,,0,
1657397143.672,,1.000000e+002,1.699929e+002,3.202330e-004,2.733783e-007,3,9.724416e-001,8.536855e-002,,,,,,,,,,,,,,48,2,4.000000e+000,1.329041e-002,0.000000e+000,0,,0,
1657397663.253,,1.000000e+002,1.799941e+002,2.854744e-004,1.744526e-007,3,9.725174e-001,6.110970e-002,,,,,,,,,,,,,,48,2,4.000000e+000,1.480103e-002,0.000000e+000,0,,0,
1657398200.927,,1.000000e+002,1.899900e+002,2.567043e-004,1.502305e-008,3,9.726158e-001,5.852276e-003,,,,,,,,,,,,,,48,2,4.000000e+000,8.300781e-003,0.000000e+000,0,,0,
1657398716.823,,1.000000e+002,1.999862e+002,2.328677e-004,2.254486e-007,3,9.728120e-001,9.681404e-002,,,,,,,,,,,,,,48,2,4.000000e+000,2.740479e-002,0.000000e+000,0,,0,
1657399095.116,,1.000000e+002,2.099980e+002,2.123931e-004,1.173753e-007,3,9.731815e-001,5.526321e-002,,,,,,,,,,,,,,48,2,4.000000e+000,2.999878e-002,0.000000e+000,0,,0,
1657399610.390,,1.000000e+002,2.199846e+002,1.952324e-004,1.254939e-007,3,9.733336e-001,6.427923e-002,,,,,,,,,,,,,,48,2,4.000000e+000,2.189636e-002,0.000000e+000,0,,0,
1657400123.897,,1.000000e+002,2.299904e+002,1.802816e-004,1.133828e-007,3,9.735216e-001,6.289207e-002,,,,,,,,,,,,,,48,2,4.000000e+000,2.400208e-002,0.000000e+000,0,,0,
1657400635.757,,1.000000e+002,2.399900e+002,1.673621e-004,9.761893e-008,3,9.738586e-001,5.832799e-002,,,,,,,,,,,,,,48,2,4.000000e+000,2.610779e-002,0.000000e+000,0,,0,
1657401010.094,,1.000000e+002,2.499799e+002,1.560267e-004,1.142266e-007,3,9.739258e-001,7.320966e-002,,,,,,,,,,,,,,48,2,4.000000e+000,1.420593e-002,0.000000e+000,0,,0,
1657401517.959,,1.000000e+002,2.600001e+002,1.461887e-004,1.237035e-007,3,9.739997e-001,8.461902e-002,,,,,,,,,,,,,,48,2,4.000000e+000,1.522827e-002,0.000000e+000,0,,0,
1657402021.107,,1.000000e+002,2.699999e+002,1.373253e-004,1.142883e-007,3,9.740874e-001,8.322454e-002,,,,,,,,,,,,,,48,2,4.000000e+000,3.302002e-002,0.000000e+000,0,,0,
1657402546.611,,1.000000e+002,2.799917e+002,1.294396e-004,8.499340e-009,3,9.743725e-001,6.566260e-003,,,,,,,,,,,,,,48,2,4.000000e+000,1.788330e-002,0.000000e+000,0,,0,
1657403098.262,,1.000000e+002,2.900021e+002,1.225848e-004,2.942871e-009,3,9.745342e-001,2.400681e-003,,,,,,,,,,,,,,48,2,4.000000e+000,1.907349e-002,0.000000e+000,0,,0,
1657403627.297,,1.000000e+002,3.000033e+002,1.163921e-004,1.840323e-008,3,9.747316e-001,1.581140e-002,,,,,,,,,,,,,,48,2,4.000000e+000,2.059937e-002,0.000000e+000,0,,0,
1657412099.070,,1.000000e+002,5.001862e+000,5.615201e-002,3.532434e-006,3,9.650595e-001,6.290841e-003,,,,,,,,,,,,,,48,2,4.000000e+000,1.356220e-002,0.000000e+000,0,,0,
1657412350.477,,1.000000e+002,1.000231e+001,5.773593e-002,1.975809e-007,3,9.650309e-001,3.422148e-004,,,,,,,,,,,,,,48,2,4.000000e+000,1.284409e-002,0.000000e+000,0,,0,
1657412589.749,,1.000000e+002,1.499841e+001,6.192133e-002,2.547252e-006,3,9.647146e-001,4.113690e-003,,,,,,,,,,,,,,48,2,4.000000e+000,3.839493e-003,0.000000e+000,0,,0,
1657412811.159,,1.000000e+002,1.999984e+001,6.456545e-002,6.295688e-006,3,9.645532e-001,9.750862e-003,,,,,,,,,,,,,,48,2,4.000000e+000,1.329422e-003,0.000000e+000,0,,0,
1657413024.111,,1.000000e+002,2.500066e+001,6.219672e-002,6.416858e-006,3,9.647344e-001,1.031704e-002,,,,,,,,,,,,,,48,2,4.000000e+000,5.990982e-003,0.000000e+000,0,,0,
1657413216.611,,1.000000e+002,3.000127e+001,5.463089e-002,4.807376e-006,3,9.654100e-001,8.799739e-003,,,,,,,,,,,,,,48,2,4.000000e+000,4.171371e-003,0.000000e+000,0,,0,
1657413433.294,,1.000000e+002,3.500287e+001,4.173226e-002,0.000000e+000,3,9.668339e-001,0.000000e+000,,,,,,,,,,,,,,48,2,4.000000e+000,5.531311e-003,0.000000e+000,0,,0,
1657413683.439,,1.000000e+002,4.000092e+001,2.816078e-002,9.311829e-007,3,9.680332e-001,3.306666e-003,,,,,,,,,,,,,,48,2,4.000000e+000,5.641937e-003,0.000000e+000,0,,0,
1657414048.780,,1.000000e+002,4.499936e+001,1.849569e-002,5.415870e-006,3,9.687876e-001,2.928180e-002,,,,,,,,,,,,,,48,2,4.000000e+000,3.490448e-003,0.000000e+000,0,,0,
1657414408.292,,1.000000e+002,5.000140e+001,1.262233e-002,7.836957e-008,3,9.687059e-001,6.208805e-004,,,,,,,,,,,,,,48,2,4.000000e+000,1.411438e-003,0.000000e+000,0,,0,
1657414731.063,,1.000000e+002,5.500143e+001,9.007260e-003,3.344748e-006,3,9.685819e-001,3.713391e-002,,,,,,,,,,,,,,48,2,4.000000e+000,6.710052e-003,0.000000e+000,0,,0,
1657415093.632,,1.000000e+002,6.000082e+001,6.651654e-003,5.419821e-007,3,9.683190e-001,8.148081e-003,,,,,,,,,,,,,,48,2,4.000000e+000,5.920410e-003,0.000000e+000,0,,0,
1657415452.715,,1.000000e+002,6.499627e+001,5.048030e-003,1.896938e-006,3,9.686379e-001,3.757778e-002,,,,,,,,,,,,,,48,2,4.000000e+000,6.843567e-003,0.000000e+000,0,,0,
1657415829.371,,1.000000e+002,6.998930e+001,3.909471e-003,1.973329e-006,3,9.688032e-001,5.047560e-002,,,,,,,,,,,,,,48,2,4.000000e+000,5.218506e-003,0.000000e+000,0,,0,
1657416223.007,,1.000000e+002,7.499234e+001,3.086454e-003,2.142904e-006,3,9.692553e-001,6.942931e-002,,,,,,,,,,,,,,48,2,4.000000e+000,2.975464e-003,0.000000e+000,0,,0,
1657416650.503,,1.000000e+002,7.999147e+001,2.478482e-003,2.341126e-007,3,9.695984e-001,9.445807e-003,,,,,,,,,,,,,,48,2,4.000000e+000,6.675720e-003,0.000000e+000,0,,0,
1657417072.760,,1.000000e+002,8.499039e+001,2.022530e-003,1.398913e-006,3,9.702792e-001,6.916650e-002,,,,,,,,,,,,,,48,2,4.000000e+000,3.723145e-003,0.000000e+000,0,,0,
1657417496.717,,1.000000e+002,9.000388e+001,1.674118e-003,1.156733e-006,3,9.708315e-001,6.909508e-002,,,,,,,,,,,,,,48,2,4.000000e+000,1.242828e-002,0.000000e+000,0,,0,
1657417934.476,,1.000000e+002,9.498854e+001,1.404671e-003,1.710981e-006,3,9.712140e-001,1.218066e-001,,,,,,,,,,,,,,48,2,4.000000e+000,9.155273e-003,0.000000e+000,0,,0,
1657418384.716,,1.000000e+002,9.999163e+001,1.197230e-003,8.678794e-007,3,9.716505e-001,7.249063e-002,,,,,,,,,,,,,,48,2,4.000000e+000,1.503754e-002,0.000000e+000,0,,0,
1657418895.910,,1.000000e+002,1.099921e+002,9.018128e-004,5.333799e-007,3,9.721606e-001,5.914530e-002,,,,,,,,,,,,,,48,2,4.000000e+000,2.998352e-003,0.000000e+000,0,,0,
1657419441.678,,1.000000e+002,1.199917e+002,7.125215e-004,1.383767e-007,3,9.722660e-001,1.942070e-002,,,,,,,,,,,,,,48,2,4.000000e+000,3.501892e-003,0.000000e+000,0,,0,
1657419961.578,,1.000000e+002,1.299946e+002,5.833117e-004,5.549472e-007,3,9.723697e-001,9.513735e-002,,,,,,,,,,,,,,48,2,4.000000e+000,4.089355e-003,0.000000e+000,0,,0,
1657420483.605,,1.000000e+002,1.399908e+002,4.896867e-004,3.854955e-007,3,9.725548e-001,7.872287e-002,,,,,,,,,,,,,,48,2,4.000000e+000,1.390076e-002,0.000000e+000,0,,0,
1657421002.722,,1.000000e+002,1.499881e+002,4.190459e-004,3.606354e-007,3,9.724767e-001,8.606108e-002,,,,,,,,,,,,,,48,2,4.000000e+000,1.579285e-002,0.000000e+000,0,,0,
1657421521.697,,1.000000e+002,1.599920e+002,3.645897e-004,3.328942e-007,3,9.725679e-001,9.130654e-002,,,,,,,,,,,,,,48,2,4.000000e+000,1.179504e-002,0.000000e+000,0,,0,
1657422037.667,,1.000000e+002,1.699895e+002,3.213710e-004,2.576555e-007,3,9.726121e-001,8.017386e-002,,,,,,,,,,,,,,48,2,4.000000e+000,1.329041e-002,0.000000e+000,0,,0,
1657422554.605,,1.000000e+002,1.799922e+002,2.865608e-004,1.877058e-007,3,9.726309e-001,6.550295e-002,,,,,,,,,,,,,,48,2,4.000000e+000,2.229309e-002,0.000000e+000,0,,0,
1657423088.095,,1.000000e+002,1.899900e+002,2.577131e-004,1.500248e-008,3,9.726990e-001,5.821388e-003,,,,,,,,,,,,,,48,2,4.000000e+000,1.649475e-002,0.000000e+000,0,,0,
1657423602.878,,1.000000e+002,1.999953e+002,2.338713e-004,1.609936e-007,3,9.727618e-001,6.883852e-002,,,,,,,,,,,,,,48,2,4.000000e+000,9.201050e-003,0.000000e+000,0,,0,
1657424118.249,,1.000000e+002,2.099880e+002,2.135813e-004,8.888293e-008,3,9.728782e-001,4.161549e-002,,,,,,,,,,,,,,48,2,4.000000e+000,9.994507e-003,0.000000e+000,0,,0,
1657424634.785,,1.000000e+002,2.199901e+002,1.961641e-004,1.415150e-007,3,9.731169e-001,7.214116e-002,,,,,,,,,,,,,,48,2,4.000000e+000,2.189636e-002,0.000000e+000,0,,0,
1657425147.323,,1.000000e+002,2.299934e+002,1.811299e-004,1.883849e-007,3,9.735073e-001,1.040054e-001,,,,,,,,,,,,,,48,2,4.000000e+000,2.400208e-002,0.000000e+000,0,,0,
1657425659.400,,1.000000e+002,2.399834e+002,1.680635e-004,1.195361e-007,3,9.738274e-001,7.112556e-002,,,,,,,,,,,,,,48,2,4.000000e+000,2.600098e-002,0.000000e+000,0,,0,
1657426166.347,,1.000000e+002,2.499870e+002,1.566691e-004,1.098123e-007,3,9.738698e-001,7.009188e-002,,,,,,,,,,,,,,48,2,4.000000e+000,1.409912e-002,0.000000e+000,0,,0,
1657426674.965,,1.000000e+002,2.599963e+002,1.466715e-004,1.031445e-007,3,9.740476e-001,7.032352e-002,,,,,,,,,,,,,,48,2,4.000000e+000,1.531982e-002,0.000000e+000,0,,0,
1657427180.650,,1.000000e+002,2.699978e+002,1.377662e-004,1.115204e-007,3,9.742172e-001,8.094903e-002,,,,,,,,,,,,,,48,2,4.000000e+000,2.481079e-002,0.000000e+000,0,,0,
1657427709.395,,1.000000e+002,2.799939e+002,1.298313e-004,4.759013e-008,3,9.741912e-001,3.665535e-002,,,,,,,,,,,,,,48,2,4.000000e+000,1.788330e-002,0.000000e+000,0,,0,
1657428214.846,,1.000000e+002,2.900021e+002,1.229544e-004,9.719705e-008,3,9.745008e-001,7.905132e-002,,,,,,,,,,,,,,48,2,4.000000e+000,1.907349e-002,0.000000e+000,0,,0,
1657428722.259,,1.000000e+002,3.000084e+002,1.167529e-004,8.039387e-008,3,9.747437e-001,6.885811e-002,,,,,,,,,,,,,,48,2,4.000000e+000,1.028442e-002,0.000000e+000,0,,0,
1657439364.182,,0.000000e+000,5.002400e+000,1.287438e-005,1.203497e-007,2,0.000000e+000,9.347993e-001,,,,,,,,,,,,,,48,2,4.000000e+000,9.669781e-003,0.000000e+000,0,,0,
1657439584.280,,1.000000e+003,5.000522e+000,1.864337e-001,1.497267e-005,3,9.730465e-001,8.031096e-003,,,,,,,,,,,,,,48,2,4.000000e+000,3.252029e-003,0.000000e+000,0,,0,
1657439872.144,,2.000000e+003,5.002538e+000,2.293715e-001,2.922568e-004,3,9.746032e-001,1.274163e-001,,,,,,,,,,,,,,48,2,4.000000e+000,1.113415e-002,0.000000e+000,0,,0,
1657440141.345,,3.000000e+003,5.000093e+000,2.523421e-001,3.590490e-004,3,9.751633e-001,1.422866e-001,,,,,,,,,,,,,,48,2,4.000000e+000,1.444817e-003,0.000000e+000,0,,0,
1657440412.932,,4.000000e+003,4.999709e+000,2.679907e-001,3.642120e-004,3,9.752367e-001,1.359047e-001,,,,,,,,,,,,,,48,2,4.000000e+000,6.318092e-004,0.000000e+000,0,,0,
1657440676.164,,5.000000e+003,5.000002e+000,2.801394e-001,4.022284e-004,3,9.754034e-001,1.435815e-001,,,,,,,,,,,,,,48,2,4.000000e+000,1.082897e-003,0.000000e+000,0,,0,
1657440951.545,,6.000000e+003,5.000115e+000,2.901528e-001,5.308185e-004,3,9.754636e-001,1.829444e-001,,,,,,,,,,,,,,48,2,4.000000e+000,1.173973e-003,0.000000e+000,0,,0,
1657441215.595,,7.000000e+003,5.000071e+000,2.986307e-001,4.577780e-004,3,9.755903e-001,1.532924e-001,,,,,,,,,,,,,,48,2,4.000000e+000,9.927750e-004,0.000000e+000,0,,0,
1657441471.715,,8.000000e+003,5.000115e+000,3.062146e-001,5.404491e-004,3,9.757739e-001,1.764936e-001,,,,,,,,,,,,,,48,2,4.000000e+000,1.264095e-003,0.000000e+000,0,,0,
1657441729.463,,9.000000e+003,4.999980e+000,3.128513e-001,4.865432e-004,3,9.757847e-001,1.555190e-001,,,,,,,,,,,,,,48,2,4.000000e+000,1.083374e-003,0.000000e+000,0,,0,
1657441986.530,,1.000000e+004,4.999958e+000,3.189098e-001,5.340427e-004,3,9.758677e-001,1.674588e-001,,,,,,,,,,,,,,48,2,4.000000e+000,1.173019e-003,0.000000e+000,0,,0,
1657442141.001,,1.000000e+004,5.005435e+000,3.183557e-001,8.501019e-005,3,9.752961e-001,2.670290e-002,,,,,,,,,,,,,,48,2,4.000000e+000,1.240587e-002,0.000000e+000,0,,0,
1657442414.058,,1.500000e+004,5.000228e+000,3.434108e-001,8.187447e-004,3,9.760890e-001,2.384156e-001,,,,,,,,,,,,,,48,2,4.000000e+000,1.811981e-004,0.000000e+000,0,,0,
1657442691.265,,2.000000e+004,4.999867e+000,3.615689e-001,8.225379e-004,3,9.763511e-001,2.274913e-001,,,,,,,,,,,,,,48,2,4.000000e+000,1.084328e-003,0.000000e+000,0,,0,
1657442971.987,,2.500000e+004,5.000115e+000,3.761482e-001,7.244622e-004,3,9.764219e-001,1.926002e-001,,,,,,,,,,,,,,48,2,4.000000e+000,1.534939e-003,0.000000e+000,0,,0,
1657443250.054,,3.000000e+004,4.999799e+000,3.885279e-001,7.694539e-004,3,9.763854e-001,1.980434e-001,,,,,,,,,,,,,,48,2,4.000000e+000,1.354218e-003,0.000000e+000,0,,0,
1657443521.780,,3.500000e+004,5.000206e+000,3.993199e-001,7.534382e-004,3,9.763658e-001,1.886804e-001,,,,,,,,,,,,,,48,2,4.000000e+000,1.625061e-003,0.000000e+000,0,,0,
1657443796.875,,4.000000e+004,5.000025e+000,4.089657e-001,7.340717e-004,3,9.764635e-001,1.794947e-001,,,,,,,,,,,,,,48,2,4.000000e+000,1.354218e-003,0.000000e+000,0,,0,
1657444074.188,,4.500000e+004,5.001721e+000,4.177736e-001,6.845912e-004,3,9.765806e-001,1.638665e-001,,,,,,,,,,,,,,48,2,4.000000e+000,7.777691e-003,0.000000e+000,0,,0,
1657444349.391,,5.000000e+004,4.999663e+000,4.257776e-001,6.533394e-004,3,9.764839e-001,1.534462e-001,,,,,,,,,,,,,,48,2,4.000000e+000,1.174450e-003,0.000000e+000,0,,0,
1657444620.369,,5.500000e+004,5.000003e+000,4.333689e-001,7.711609e-004,3,9.767056e-001,1.779456e-001,,,,,,,,,,,,,,48,2,4.000000e+000,1.263618e-003,0.000000e+000,0,,0,
1657444897.812,,6.000000e+004,4.999642e+000,4.404373e-001,7.858701e-004,3,9.767179e-001,1.784295e-001,,,,,,,,,,,,,,48,2,4.000000e+000,1.264095e-003,0.000000e+000,0,,0,
1657445176.801,,6.500000e+004,4.999867e+000,4.471043e-001,7.050536e-004,3,9.767743e-001,1.576933e-001,,,,,,,,,,,,,,48,2,4.000000e+000,1.084328e-003,0.000000e+000,0,,0,
1657445452.928,,7.000000e+004,4.999889e+000,4.545842e-001,7.808125e-004,3,9.770482e-001,1.717641e-001,,,,,,,,,,,,,,48,2,4.000000e+000,1.264095e-003,0.000000e+000,0,,0,
1657445603.316,,7.000000e+004,4.999732e+000,4.536074e-001,2.163187e-004,3,9.764388e-001,4.768853e-002,,,,,,,,,,,,,,48,2,4.000000e+000,1.354218e-003,0.000000e+000,0,,0,
1657445891.820,,6.500000e+004,4.999731e+000,4.474559e-001,9.242593e-004,3,9.769044e-001,2.065587e-001,,,,,,,,,,,,,,48,2,4.000000e+000,7.219315e-004,0.000000e+000,0,,0,
1657446172.217,,6.000000e+004,4.999845e+000,4.407873e-001,9.180005e-004,3,9.769356e-001,2.082638e-001,,,,,,,,,,,,,,48,2,4.000000e+000,9.932518e-004,0.000000e+000,0,,0,
1657446449.414,,5.500000e+004,5.000070e+000,4.336492e-001,8.152676e-004,3,9.768614e-001,1.880016e-001,,,,,,,,,,,,,,48,2,4.000000e+000,1.264095e-003,0.000000e+000,0,,0,
1657446738.034,,5.000000e+004,4.999845e+000,4.261365e-001,7.688850e-004,3,9.768445e-001,1.804316e-001,,,,,,,,,,,,,,48,2,4.000000e+000,5.407333e-004,0.000000e+000,0,,0,
1657447016.822,,4.500000e+004,4.999732e+000,4.180294e-001,6.624853e-004,3,9.767294e-001,1.584782e-001,,,,,,,,,,,,,,48,2,4.000000e+000,5.421638e-004,0.000000e+000,0,,0,
1657447262.394,,4.000000e+004,4.999822e+000,4.089828e-001,7.771247e-004,3,9.765276e-001,1.900140e-001,,,,,,,,,,,,,,48,2,4.000000e+000,4.506111e-004,0.000000e+000,0,,0,
1657447545.774,,3.500000e+004,5.000635e+000,3.995636e-001,6.041329e-004,3,9.766997e-001,1.511982e-001,,,,,,,,,,,,,,48,2,4.000000e+000,4.064083e-003,0.000000e+000,0,,0,
1657447824.185,,3.000000e+004,5.000047e+000,3.887316e-001,5.823430e-004,3,9.766715e-001,1.498059e-001,,,,,,,,,,,,,,48,2,4.000000e+000,1.083851e-003,0.000000e+000,0,,0,
1657448100.846,,2.500000e+004,4.999845e+000,3.763660e-001,5.759156e-004,3,9.765890e-001,1.530201e-001,,,,,,,,,,,,,,48,2,4.000000e+000,9.031296e-004,0.000000e+000,0,,0,
1657448382.992,,2.000000e+004,4.999686e+000,3.616627e-001,5.384471e-004,3,9.764612e-001,1.488810e-001,,,,,,,,,,,,,,48,2,4.000000e+000,9.927750e-004,0.000000e+000,0,,0,
1657448667.484,,1.500000e+004,5.000319e+000,3.436449e-001,3.471425e-004,3,9.763843e-001,1.010178e-001,,,,,,,,,,,,,,48,2,4.000000e+000,1.716137e-003,0.000000e+000,0,,0,
1657448944.654,,1.000000e+004,5.000161e+000,3.195318e-001,2.260335e-004,3,9.761486e-001,7.073899e-002,,,,,,,,,,,,,,48,2,4.000000e+000,5.412102e-004,0.000000e+000,0,,0,
1657449093.823,,1.000000e+004,4.999799e+000,3.189965e-001,2.001343e-004,3,9.756531e-001,6.273871e-002,,,,,,,,,,,,,,48,2,4.000000e+000,1.714706e-003,0.000000e+000,0,,0,
1657449314.657,,9.000000e+003,5.000025e+000,3.130995e-001,5.184905e-004,3,9.754806e-001,1.655993e-001,,,,,,,,,,,,,,48,2,4.000000e+000,1.083374e-003,0.000000e+000,0,,0,
1657449566.110,,8.000000e+003,4.999913e+000,3.064455e-001,2.537240e-004,3,9.756931e-001,8.279581e-002,,,,,,,,,,,,,,48,2,4.000000e+000,7.219315e-004,0.000000e+000,0,,0,
1657449834.005,,7.000000e+003,4.999958e+000,2.988677e-001,2.797286e-004,3,9.756161e-001,9.359615e-002,,,,,,,,,,,,,,48,2,4.000000e+000,4.520416e-004,0.000000e+000,0,,0,
1657450097.192,,6.000000e+003,4.999777e+000,2.904150e-001,2.880526e-004,3,9.755701e-001,9.918654e-002,,,,,,,,,,,,,,48,2,4.000000e+000,7.219315e-004,0.000000e+000,0,,0,
1657450366.415,,5.000000e+003,4.999867e+000,2.804443e-001,2.386776e-004,3,9.753861e-001,8.510697e-002,,,,,,,,,,,,,,48,2,4.000000e+000,9.031296e-004,0.000000e+000,0,,0,
1657450634.146,,4.000000e+003,5.000003e+000,2.683504e-001,1.982798e-004,3,9.752035e-001,7.388841e-002,,,,,,,,,,,,,,48,2,4.000000e+000,1.263618e-003,0.000000e+000,0,,0,
1657450903.898,,3.000000e+003,4.999686e+000,2.528290e-001,1.445005e-004,3,9.749119e-001,5.715345e-002,,,,,,,,,,,,,,48,2,4.000000e+000,3.619194e-004,0.000000e+000,0,,0,
1657451172.616,,2.000000e+003,4.999732e+000,2.307073e-001,2.586025e-004,3,9.747904e-001,1.120912e-001,,,,,,,,,,,,,,48,2,4.000000e+000,1.264095e-003,0.000000e+000,0,,0,
1657451437.646,,1.000000e+003,4.999980e+000,1.903803e-001,9.065787e-005,3,9.733560e-001,4.761935e-002,,,,,,,,,,,,,,48,2,4.000000e+000,9.016991e-004,0.000000e+000,0,,0,
1657451662.879,,0.000000e+000,4.996284e+000,2.849246e-002,1.572038e-004,3,9.550928e-001,5.517383e-001,,,,,,,,,,,,,,48,2,4.000000e+000,5.678654e-003,0.000000e+000,0,,0,
1657451948.317,,-1.000000e+003,5.000183e+000,-1.883038e-001,2.948383e-004,3,9.741335e-001,1.565759e-001,,,,,,,,,,,,,,48,2,4.000000e+000,5.407333e-004,0.000000e+000,0,,0,
1657452212.070,,-2.000000e+003,5.000048e+000,-2.300894e-001,4.125017e-004,3,9.750705e-001,1.792789e-001,,,,,,,,,,,,,,48,2,4.000000e+000,6.322861e-004,0.000000e+000,0,,0,
1657452474.909,,-3.000000e+003,5.000138e+000,-2.525660e-001,4.519617e-004,3,9.752951e-001,1.789480e-001,,,,,,,,,,,,,,48,2,4.000000e+000,4.510880e-004,0.000000e+000,0,,0,
1657452742.940,,-4.000000e+003,5.000002e+000,-2.681041e-001,3.694382e-004,3,9.753828e-001,1.377965e-001,,,,,,,,,,,,,,48,2,4.000000e+000,6.318092e-004,0.000000e+000,0,,0,
1657453011.520,,-5.000000e+003,5.000025e+000,-2.802472e-001,4.123437e-004,3,9.755476e-001,1.471357e-001,,,,,,,,,,,,,,48,2,4.000000e+000,7.224083e-004,0.000000e+000,0,,0,
1657453280.206,,-6.000000e+003,5.000161e+000,-2.901571e-001,4.248613e-004,3,9.755672e-001,1.464245e-001,,,,,,,,,,,,,,48,2,4.000000e+000,8.120537e-004,0.000000e+000,0,,0,
1657453551.019,,-7.000000e+003,5.000161e+000,-2.986584e-001,4.187500e-004,3,9.756900e-001,1.402104e-001,,,,,,,,,,,,,,48,2,4.000000e+000,1.353741e-003,0.000000e+000,0,,0,
1657453806.927,,-8.000000e+003,4.999845e+000,-3.062095e-001,5.065419e-004,3,9.757044e-001,1.654233e-001,,,,,,,,,,,,,,48,2,4.000000e+000,4.506111e-004,0.000000e+000,0,,0,
1657454061.789,,-9.000000e+003,4.999935e+000,-3.129246e-001,5.530299e-004,3,9.758444e-001,1.767295e-001,,,,,,,,,,,,,,48,2,4.000000e+000,6.322861e-004,0.000000e+000,0,,0,
1657454318.582,,-1.000000e+004,4.999732e+000,-3.189185e-001,5.124846e-004,3,9.758496e-001,1.606945e-001,,,,,,,,,,,,,,48,2,4.000000e+000,1.811981e-004,0.000000e+000,0,,0,
1657454472.203,,-1.000000e+004,4.999619e+000,-3.184042e-001,6.798287e-005,3,9.753971e-001,2.135112e-002,,,,,,,,,,,,,,48,2,4.000000e+000,2.166271e-003,0.000000e+000,0,,0,
1657454745.440,,-1.500000e+004,4.999822e+000,-3.434417e-001,7.871556e-004,3,9.761153e-001,2.291963e-001,,,,,,,,,,,,,,48,2,4.000000e+000,8.130074e-004,0.000000e+000,0,,0,
1657455015.137,,-2.000000e+004,5.000093e+000,-3.617702e-001,9.207190e-004,3,9.764266e-001,2.545038e-001,,,,,,,,,,,,,,48,2,4.000000e+000,1.444340e-003,0.000000e+000,0,,0,
1657455281.078,,-2.500000e+004,5.000093e+000,-3.763957e-001,9.324147e-004,3,9.764531e-001,2.477219e-001,,,,,,,,,,,,,,48,2,4.000000e+000,9.927750e-004,0.000000e+000,0,,0,
1657455560.740,,-3.000000e+004,5.000002e+000,-3.885902e-001,6.851813e-004,3,9.764137e-001,1.763249e-001,,,,,,,,,,,,,,48,2,4.000000e+000,4.520416e-004,0.000000e+000,0,,0,
1657455831.346,,-3.500000e+004,5.000319e+000,-3.994251e-001,7.466525e-004,3,9.763863e-001,1.869318e-001,,,,,,,,,,,,,,48,2,4.000000e+000,9.021759e-004,0.000000e+000,0,,0,
1657456100.097,,-4.000000e+004,5.000183e+000,-4.091344e-001,7.633005e-004,3,9.765007e-001,1.865647e-001,,,,,,,,,,,,,,48,2,4.000000e+000,1.354694e-003,0.000000e+000,0,,0,
1657456374.022,,-4.500000e+004,5.000048e+000,-4.178879e-001,6.951912e-004,3,9.765371e-001,1.663583e-001,,,,,,,,,,,,,,48,2,4.000000e+000,1.263618e-003,0.000000e+000,0,,0,
1657456642.888,,-5.000000e+004,4.999506e+000,-4.260482e-001,7.925293e-004,3,9.765939e-001,1.860187e-001,,,,,,,,,,,,,,48,2,4.000000e+000,1.625061e-003,0.000000e+000,0,,0,
1657456918.858,,-5.500000e+004,5.000138e+000,-4.334933e-001,7.153795e-004,3,9.766625e-001,1.650267e-001,,,,,,,,,,,,,,48,2,4.000000e+000,1.264095e-003,0.000000e+000,0,,0,
1657457203.413,,-6.000000e+004,4.999799e+000,-4.405134e-001,6.774684e-004,3,9.767199e-001,1.537907e-001,,,,,,,,,,,,,,48,2,4.000000e+000,1.444340e-003,0.000000e+000,0,,0,
1657457474.163,,-6.500000e+004,4.999664e+000,-4.474064e-001,8.427894e-004,3,9.768597e-001,1.883723e-001,,,,,,,,,,,,,,48,2,4.000000e+000,1.443863e-003,0.000000e+000,0,,0,
1657457755.213,,-7.000000e+004,4.999822e+000,-4.547755e-001,7.540704e-004,3,9.771417e-001,1.658116e-001,,,,,,,,,,,,,,48,2,4.000000e+000,1.811981e-004,0.000000e+000,0,,0,
1657457907.574,,-7.000000e+004,5.003060e+000,-4.537867e-001,1.691142e-004,3,9.764776e-001,3.726734e-002,,,,,,,,,,,,,,48,2,4.000000e+000,1.295233e-002,0.000000e+000,0,,0,
1657458196.270,,-6.500000e+004,4.999574e+000,-4.475577e-001,8.880552e-004,3,9.769408e-001,1.984225e-001,,,,,,,,,,,,,,48,2,4.000000e+000,1.805305e-003,0.000000e+000,0,,0,
1657458477.813,,-6.000000e+004,5.000658e+000,-4.409171e-001,8.572880e-004,3,9.770156e-001,1.944329e-001,,,,,,,,,,,,,,48,2,4.000000e+000,3.973961e-003,0.000000e+000,0,,0,
1657458758.161,,-5.500000e+004,5.000025e+000,-4.338256e-001,7.738583e-004,3,9.769326e-001,1.783800e-001,,,,,,,,,,,,,,48,2,4.000000e+000,6.322861e-004,0.000000e+000,0,,0,
1657459046.024,,-5.000000e+004,5.000138e+000,-4.262999e-001,7.636799e-004,3,9.769913e-001,1.791414e-001,,,,,,,,,,,,,,48,2,4.000000e+000,9.927750e-004,0.000000e+000,0,,0,
1657459325.794,,-4.500000e+004,4.999935e+000,-4.182007e-001,7.153163e-004,3,9.768194e-001,1.710462e-001,,,,,,,,,,,,,,48,2,4.000000e+000,1.264095e-003,0.000000e+000,0,,0,
1657459603.783,,-4.000000e+004,5.000838e+000,-4.093171e-001,6.708935e-004,3,9.767264e-001,1.639056e-001,,,,,,,,,,,,,,48,2,4.000000e+000,4.336834e-003,0.000000e+000,0,,0,
1657459882.327,,-3.500000e+004,5.000093e+000,-3.996647e-001,5.667276e-004,3,9.767045e-001,1.418008e-001,,,,,,,,,,,,,,48,2,4.000000e+000,9.031296e-004,0.000000e+000,0,,0,
1657460165.864,,-3.000000e+004,5.000228e+000,-3.888493e-001,5.819848e-004,3,9.766909e-001,1.496685e-001,,,,,,,,,,,,,,48,2,4.000000e+000,9.932518e-004,0.000000e+000,0,,0,
1657460441.542,,-2.500000e+004,4.999867e+000,-3.764592e-001,5.465393e-004,3,9.765838e-001,1.451789e-001,,,,,,,,,,,,,,48,2,4.000000e+000,5.407333e-004,0.000000e+000,0,,0,
1657460718.269,,-2.000000e+004,5.000273e+000,-3.618772e-001,5.240750e-004,3,9.765513e-001,1.448212e-001,,,,,,,,,,,,,,48,2,4.000000e+000,1.264095e-003,0.000000e+000,0,,0,
1657460994.111,,-1.500000e+004,5.000071e+000,-3.438537e-001,3.619571e-004,3,9.763694e-001,1.052649e-001,,,,,,,,,,,,,,48,2,4.000000e+000,1.533985e-003,0.000000e+000,0,,0,
1657461268.154,,-1.000000e+004,4.999957e+000,-3.196900e-001,2.310280e-004,3,9.761198e-001,7.226624e-002,,,,,,,,,,,,,,48,2,4.000000e+000,6.322861e-004,0.000000e+000,0,,0,
1657461418.677,,-1.000000e+004,5.000816e+000,-3.191112e-001,1.639934e-004,3,9.757053e-001,5.139067e-002,,,,,,,,,,,,,,48,2,4.000000e+000,3.432751e-003,0.000000e+000,0,,0,
1657461676.995,,-9.000000e+003,5.000726e+000,-3.133124e-001,2.850391e-004,3,9.758872e-001,9.097601e-002,,,,,,,,,,,,,,48,2,4.000000e+000,4.065990e-003,0.000000e+000,0,,0,
1657461929.591,,-8.000000e+003,5.000025e+000,-3.065892e-001,3.034995e-004,3,9.757657e-001,9.899221e-002,,,,,,,,,,,,,,48,2,4.000000e+000,1.264095e-003,0.000000e+000,0,,0,
1657462199.666,,-7.000000e+003,4.999844e+000,-2.989748e-001,2.194797e-004,3,9.756238e-001,7.341079e-002,,,,,,,,,,,,,,48,2,4.000000e+000,9.927750e-004,0.000000e+000,0,,0,
1657462471.976,,-6.000000e+003,5.000951e+000,-2.904989e-001,2.520382e-004,3,9.755397e-001,8.676045e-002,,,,,,,,,,,,,,48,2,4.000000e+000,3.613949e-003,0.000000e+000,0,,0,
1657462737.187,,-5.000000e+003,5.000093e+000,-2.805423e-001,2.563793e-004,3,9.753852e-001,9.138702e-002,,,,,,,,,,,,,,48,2,4.000000e+000,9.927750e-004,0.000000e+000,0,,0,
1657463011.930,,-4.000000e+003,5.000093e+000,-2.684565e-001,2.076364e-004,3,9.752561e-001,7.734454e-002,,,,,,,,,,,,,,48,2,4.000000e+000,5.421638e-004,0.000000e+000,0,,0,
1657463280.615,,-3.000000e+003,5.000274e+000,-2.529401e-001,1.252604e-004,3,9.750714e-001,4.952177e-002,,,,,,,,,,,,,,48,2,4.000000e+000,7.219315e-004,0.000000e+000,0,,0,
1657463550.890,,-2.000000e+003,4.999889e+000,-2.307154e-001,2.066565e-004,3,9.745624e-001,8.957207e-002,,,,,,,,,,,,,,48,2,4.000000e+000,9.927750e-004,0.000000e+000,0,,0,
1657463816.658,,-1.000000e+003,5.000274e+000,-1.904816e-001,1.413394e-004,3,9.733967e-001,7.420111e-002,,,,,,,,,,,,,,48,2,4.000000e+000,9.927750e-004,0.000000e+000,0,,0,
1657464046.820,,0.000000e+000,4.997166e+000,-2.864423e-002,1.769074e-004,3,9.552597e-001,6.176023e-001,,,,,,,,,,,,,,48,2,4.000000e+000,1.001930e-002,0.000000e+000,0,,0,